Workbook

Sheet 2025
A1: REPORTE GENERAL DE ALUMNOS | B1: 20/Abr./2026
A2: UNIDADES: MITRAS
B3: MITRAS 2025-2026
A5: Matrícula | B5: Grupo | C5: Alumno Reinscrito
A6: 1936 | B6: 6PBMI | C6: =IFERROR(VLOOKUP(A6,'2026'!A$6:B$700,2,0),"Falta de reinscribir") -> Reinscrito
A7: 1963 | B7: 6PAMI | C7: =IFERROR(VLOOKUP(A7,'2026'!A$6:B$700,2,0),"Falta de reinscribir") -> Reinscrito
A8: 1964 | B8: 6PBMI | C8: =IFERROR(VLOOKUP(A8,'2026'!A$6:B$700,2,0),"Falta de reinscribir") -> Reinscrito
A9: 1966 | B9: 6PAMI | C9: =IFERROR(VLOOKUP(A9,'2026'!A$6:B$700,2,0),"Falta de reinscribir") -> Reinscrito
A10: 2011 | B10: 5PBMI | C10: =IFERROR(VLOOKUP(A10,'2026'!A$6:B$700,2,0),"Falta de reinscribir") -> Reinscrito
A11: 2015 | B11: 6PBMI | C11: =IFERROR(VLOOKUP(A11,'2026'!A$6:B$700,2,0),"Falta de reinscribir") -> Pendiente
A12: 2019 | B12: 5PAMI | C12: =IFERROR(VLOOKUP(A12,'2026'!A$6:B$700,2,0),"Falta de reinscribir") -> Reinscrito
A13: 2020 | B13: 6PBMI | C13: =IFERROR(VLOOKUP(A13,'2026'!A$6:B$700,2,0),"Falta de reinscribir") -> Reinscrito
A14: 2021 | B14: 6PBMI | C14: =IFERROR(VLOOKUP(A14,'2026'!A$6:B$700,2,0),"Falta de reinscribir") -> Reinscrito
A15: 2023 | B15: 5PAMI | C15: =IFERROR(VLOOKUP(A15,'2026'!A$6:B$700,2,0),"Falta de reinscribir") -> Reinscrito
A16: 2024 | B16: 5PAMI | C16: =IFERROR(VLOOKUP(A16,'2026'!A$6:B$700,2,0),"Falta de reinscribir") -> Reinscrito
A17: 2030 | B17: 5PAMI | C17: =IFERROR(VLOOKUP(A17,'2026'!A$6:B$700,2,0),"Falta de reinscribir") -> Reinscrito
... A380: 16655 | B380: 1KAMI | C380: =IFERROR(VLOOKUP(A380,'2026'!A$6:B$700,2,0),"Falta de reinscribir") -> Reinscrito
C381: =IFERROR(VLOOKUP(A381,'2026'!A$6:B$700,2,0),"Falta de reinscribir") -> Falta de reinscribir
C382: =IFERROR(VLOOKUP(A382,'2026'!A$6:B$700,2,0),"Falta de reinscribir") -> Falta de reinscribir
C383: =IFERROR(VLOOKUP(A383,'2026'!A$6:B$700,2,0),"Falta de reinscribir") -> Falta de reinscribir
C384: =IFERROR(VLOOKUP(A384,'2026'!A$6:B$700,2,0),"Falta de reinscribir") -> Falta de reinscribir
C385: =IFERROR(VLOOKUP(A385,'2026'!A$6:B$700,2,0),"Falta de reinscribir") -> Falta de reinscribir
C386: =IFERROR(VLOOKUP(A386,'2026'!A$6:B$700,2,0),"Falta de reinscribir") -> Falta de reinscribir

Sheet 2026
A1: REPORTE GENERAL DE ALUMNOS | E1: 20/Abr./2026
A2: UNIDADES: MITRAS
E3: MITRAS 2026-2027
A5: Matrícula | B5: Estatus | C5: Grado | D5: Fecha estatus | E5: Comentario estatus
A6: 1936 | B6: Reinscrito | C6: SECUNDARIA Grado 1 | D6: 19/11/2025 | E6: 5 Activación automática
A7: 1963 | B7: Reinscrito | C7: SECUNDARIA Grado 1 | D7: 31/12/2025 | E7: 5 Activación automática
A8: 1964 | B8: Reinscrito | C8: SECUNDARIA Grado 1 | D8: 01/12/2025 | E8: 5 Activación automática
A9: 1966 | B9: Reinscrito | C9: SECUNDARIA Grado 1 | D9: 03/12/2025 | E9: 5 Activación automática
A10: 2011 | B10: Reinscrito | C10: PRIMARIA Grado 6 | D10: 24/11/2025 | E10: 5 Activación automática
A11: 2015 | B11: Pendiente | C11: SECUNDARIA Grado 1 | D11: 22/09/2025
A12: 2019 | B12: Reinscrito | C12: PRIMARIA Grado 6 | D12: 24/02/2026
A13: 2020 | B13: Reinscrito | C13: SECUNDARIA Grado 1 | D13: 11/12/2025 | E13: 5 Activación automática
A14: 2021 | B14: Reinscrito | C14: SECUNDARIA Grado 1 | D14: 23/11/2025 | E14: 5 Activación automática
A15: 2023 | B15: Reinscrito | C15: PRIMARIA Grado 6 | D15: 30/12/2025 | E15: 5 Activación automática
A16: 2024 | B16: Reinscrito | C16: PRIMARIA Grado 6 | D16: 15/01/2026
A17: 2030 | B17: Reinscrito | C17: PRIMARIA Grado 6 | D17: 26/11/2025 | E17: 5 Activación automática
A18: 2035 | B18: Reinscrito | C18: PRIMARIA Grado 6 | D18: 02/03/2026 | E18: 5 Activación automática
A19: 2037 | B19: Pendiente | C19: SECUNDARIA Grado 1 | D19: 22/09/2025
A20: 2038 | B20: Pendiente | C20: PRIMARIA Grado 6 | D20: 22/09/2025
A21: 2040 | B21: Reinscrito | C21: PRIMARIA Grado 6 | D21: 09/01/2026 | E21: 5 Activación automática
A22: 2044 | B22: Reinscrito | C22: SECUNDARIA Grado 1 | D22: 02/12/2025 | E22: 5 Activación automática
A23: 2046 | B23: Reinscrito | C23: PRIMARIA Grado 6 | D23: 16/12/2025 | E23: 5 Activación automática
A24: 2061 | B24: Reinscrito | C24: PRIMARIA Grado 6 | D24: 12/12/2025 | E24: 5 Activación automática
A25: 2068 | B25: Pendiente | C25: SECUNDARIA Grado 1 | D25: 22/09/2025
A26: 2078 | B26: Reinscrito | C26: PRIMARIA Grado 6 | D26: 26/01/2026 | E26: 5 Activación automática
A27: 2080 | B27: Pendiente | C27: SECUNDARIA Grado 1 | D27: 22/09/2025
A28: 2082 | B28: Pendiente | C28: PRIMARIA Grado 6 | D28: 22/09/2025
A29: 2083 | B29: Reinscrito | C29: PRIMARIA Grado 5 | D29: 13/01/2026 | E29: 5 Activación automática
A30: 2084 | B30: Reinscrito | C30: PRIMARIA Grado 6 | D30: 11/12/2025 | E30: 5 Activación automática
A31: 2087 | B31: Reinscrito | C31: PRIMARIA Grado 5 | D31: 31/12/2025 | E31: 5 Activación automática
A32: 2088 | B32: Reinscrito | C32: PRIMARIA Grado 6 | D32: 27/02/2026 | E32: 5 Activación automática
A33: 2092 | B33: Reinscrito | C33: PRIMARIA Grado 5 | D33: 30/12/2025 | E33: 5 Activación automática
A34: 2093 | B34: Reinscrito | C34: PRIMARIA Grado 6 | D34: 02/12/2025 | E34: 5 Activación automática
A35: 2095 | B35: Reinscrito | C35: PRIMARIA Grado 5 | D35: 30/12/2025 | E35: 5 Activación automática
A36: 2097 | B36: Reinscrito | C36: PRIMARIA Grado 6 | D36: 11/12/2025 | E36: 5 Activación automática
A37: 2098 | B37: Reinscrito | C37: PRIMARIA Grado 6 | D37: 11/12/2025 | E37: 5 Activación automática
A38: 2100 | B38: Reinscrito | C38: PRIMARIA Grado 6 | D38: 14/12/2025 | E38: 5 Activación automática
A39: 2104 | B39: Reinscrito | C39: PRIMARIA Grado 6 | D39: 03/02/2026 | E39: 5 Activación automática
A40: 2105 | B40: Reinscrito | C40: PRIMARIA Grado 6 | D40: 11/02/2026
A41: 2106 | B41: Reinscrito | C41: PRIMARIA Grado 6 | D41: 11/02/2026
...

Sheet Avance de RI
A1: Grupo | B1: total de alumnos Reinscritos | C1: Total de alumnos por grupo | D1: % avance
A2: 1KAMI | B2: =COUNTIFS('2025'!B$6:B$700,"1KAMI",'2025'!C$6:C$700,"Reinscrito") -> 16 | C2: =COUNTIF('2025'!B$6:B$700,"1KAMI") -> 18 | D2: =B2/C2 -> 0.88888889
A3: 1KBMI | B3: =COUNTIFS('2025'!B$6:B$700,"1KBMI",'2025'!C$6:C$700,"Reinscrito") -> 14 | C3: =COUNTIF('2025'!B$6:B$700,"1KBMI") -> 17 | D3: =B3/C3 -> 0.82352941
A4: 1PAMI | B4: =COUNTIFS('2025'!B$6:B$700,"1PAMI",'2025'!C$6:C$700,"Reinscrito") -> 17 | C4: =COUNTIF('2025'!B$6:B$700,"1PAMI") -> 20 | D4: =B4/C4 -> 0.85
A5: 1PBMI | B5: =COUNTIFS('2025'!B$6:B$700,"1PBMI",'2025'!C$6:C$700,"Reinscrito") -> 15 | C5: =COUNTIF('2025'!B$6:B$700,"1PBMI") -> 20 | D5: =B5/C5 -> 0.75
A6: 2KAMI | B6: =COUNTIFS('2025'!B$6:B$700,"2KAMI",'2025'!C$6:C$700,"Reinscrito") -> 21 | C6: =COUNTIF('2025'!B$6:B$700,"2KAMI") -> 24 | D6: =B6/C6 -> 0.875
A7: 2KBMI | B7: =COUNTIFS('2025'!B$6:B$700,"2KBMI",'2025'!C$6:C$700,"Reinscrito") -> 18 | C7: =COUNTIF('2025'!B$6:B$700,"2KBMI") -> 22 | D7: =B7/C7 -> 0.81818182
A8: 2PAMI | B8: =COUNTIFS('2025'!B$6:B$700,"2PAMI",'2025'!C$6:C$700,"Reinscrito") -> 21 | C8: =COUNTIF('2025'!B$6:B$700,"2PAMI") -> 25 | D8: =B8/C8 -> 0.84
A9: 2PBMI | B9: =COUNTIFS('2025'!B$6:B$700,"2PBMI",'2025'!C$6:C$700,"Reinscrito") -> 17 | C9: =COUNTIF('2025'!B$6:B$700,"2PBMI") -> 24 | D9: =B9/C9 -> 0.70833333
A10: 3KAMI | B10: =COUNTIFS('2025'!B$6:B$700,"3KAMI",'2025'!C$6:C$700,"Reinscrito") -> 17 | C10: =COUNTIF('2025'!B$6:B$700,"3KAMI") -> 25 | D10: =B10/C10 -> 0.68
A11: 3KBMI | B11: =COUNTIFS('2025'!B$6:B$700,"3KBMI",'2025'!C$6:C$700,"Reinscrito") -> 19 | C11: =COUNTIF('2025'!B$6:B$700,"3KBMI") -> 25 | D11: =B11/C11 -> 0.76
A12: 3PAMI | B12: =COUNTIFS('2025'!B$6:B$700,"3PAMI",'2025'!C$6:C$700,"Reinscrito") -> 12 | C12: =COUNTIF('2025'!B$6:B$700,"3PAMI") -> 19 | D12: =B12/C12 -> 0.63157895
A13: 3PBMI | B13: =COUNTIFS('2025'!B$6:B$700,"3PBMI",'2025'!C$6:C$700,"Reinscrito") -> 13 | C13: =COUNTIF('2025'!B$6:B$700,"3PBMI") -> 19 | D13: =B13/C13 -> 0.68421053
A14: 4PAMI | B14: =COUNTIFS('2025'!B$6:B$700,"4PAMI",'2025'!C$6:C$700,"Reinscrito") -> 14 | C14: =COUNTIF('2025'!B$6:B$700,"4PAMI") -> 17 | D14: =B14/C14 -> 0.82352941
A15: 4PBMI | B15: =COUNTIFS('2025'!B$6:B$700,"4PBMI",'2025'!C$6:C$700,"Reinscrito") -> 13 | C15: =COUNTIF('2025'!B$6:B$700,"4PBMI") -> 18 | D15: =B15/C15 -> 0.72222222
A16: 5PAMI | B16: =COUNTIFS('2025'!B$6:B$700,"5PAMI",'2025'!C$6:C$700,"Reinscrito") -> 18 | C16: =COUNTIF('2025'!B$6:B$700,"5PAMI") -> 19 | D16: =B16/C16 -> 0.94736842
A17: 5PBMI | B17: =COUNTIFS('2025'!B$6:B$700,"5PBMI",'2025'!C$6:C$700,"Reinscrito") -> 14 | C17: =COUNTIF('2025'!B$6:B$700,"5PBMI") -> 19 | D17: =B17/C17 -> 0.73684211
A18: 6PAMI | B18: =COUNTIFS('2025'!B$6:B$700,"6PAMI",'2025'!C$6:C$700,"Reinscrito") -> 11 | C18: =COUNTIF('2025'!B$6:B$700,"6PAMI") -> 14 | D18: =B18/C18 -> 0.78571429
A19: 6PBMI | B19: =COUNTIFS('2025'!B$6:B$700,"6PBMI",'2025'!C$6:C$700,"Reinscrito") -> 9 | C19: =COUNTIF('2025'!B$6:B$700,"6PBMI") -> 14 | D19: =B19/C19 -> 0.64285714
A20: PNAMI | B20: =COUNTIFS('2025'!B$6:B$700,"PNAMI",'2025'!C$6:C$700,"Reinscrito") -> 15 | C20: =COUNTIF('2025'!B$6:B$700,"PNAMI") -> 16 | D20: =B20/C20 -> 0.9375
A21: Total / Unidad | B21: =SUBTOTAL(109,B2:B20)-27 -> 267 | C21: =SUBTOTAL(109,C2:C20)-33 -> 342 | D21: =B21/C21 -> 0.78070175
A22: con sexto de primaria | B22: =SUBTOTAL(109,Tabla1[total de alumnos Reinscritos]) -> 294 | C22: =SUBTOTAL(109,Tabla1[Total de alumnos por grupo]) -> 375 | D22: =Tabla1[[#Totals],[total de alumnos Reinscritos]]/Tabla1[[#Totals],[Total de alumnos por grupo]] -> 0.784
